Workbook

Sheet ALL TIME
A1: All Time Outbound Revenue: | C1: Average Revenue per Month:
A2: ='Jan Dash'!C2+'Ben Dec 25'!E25 + 'Feb Dash'!C2 -> 392900 | C2: =A2/3 -> 130966.67

Sheet Feb Dash
A1: Total Demos Set: | B1: Total Demos Shown: | C1: Total Outbound Rev:
A2: ='Ben Feb 26'!J4+'Adrian Feb 26'!G3 -> 54 | B2: ='Ben Feb 26'!J7+'Adrian Feb 26'!G8 -> 45 | C2: =SUM('Adrian Feb 26'!G13 + 'Ben Feb 26'!J12)+B11 -> 150150 | E2: % to Goal: | F2: =(C2/150000) * 100 -> 100.1
E3: % to EOM: | F3: =DAY(TODAY()) / DAY(EOMONTH(TODAY(), 6))*100 -> 70.967742
A10: Mel:
A11: Kevin (tilegallery) | B11: 12900

Sheet Ben Feb 26
A1: Date: | B1: Calls Made: | C1: Calls Answered: | D1: Demos Booked: | E1: Column 1
A2: 46055 | B2: 32 | C2: 7 | D2: 1 | I2: Total Calls Made | J2: 546 | M2: CALLS SHOWN: | N2: Date: | O2: Closed? | P2: Product
A3: 46056 | B3: 60 | C3: 12 | D3: 2 | E3: Week 1: | I3: Total calls answered | J3: =SUM(FEB_DASH[Calls Answered:]) -> 42 | M3: irasias@gmail.com | N3: 46056 | O3: 2000 | P3: GAW
A4: 46057 | B4: 90 | C4: 6 | D4: 2 | E4: =SUM(D2:D6) -> 9 | I4: Total Demos Booked | J4: =SUM(FEB_DASH[Demos Booked:]) -> 27 | M4: Bryan Thomas | N4: 46057 | P4: GAW
A5: 46058 | B5: 58 | C5: 9 | D5: 1 | I5: Ave calls/day | J5: =J2/COUNTA(FEB_DASH[Calls Made:]) -> 54.6 | M5: jennifer@stinkbalmodorblocker.com | N5: 46058 | P5: GAW | R5: Personal Tickets (Commission) | S5: $
A6: 46059 | B6: 59 | C6: 8 | D6: 3 | I6: Demos booked/day | J6: =J4/COUNTA(FEB_DASH[Demos Booked:]) -> 2.25 | M6: sophiabalexander@icloud.com | N6: 46058 | P6: Academy | R6: Bryan thomas | S6: 2500
A7: 46062 | B7: 60 | D7: 3 | I7: Total Demos Complete | J7: =COUNTA(FEB_SHOWS[CALLS SHOWN:]) -> 23 | M7: Evan O'reiley | N7: 46058 | P7: Academy | R7: jennifer@stinkbalmodorblocker.com | S7: 2750
A8: 46063 | B8: 62 | D8: 4 | E8: Week 2: | I8: Show % | J8: =J7/J4 -> 0.85185185 | M8: heidimazanec@gmail.com | N8: 46062 | O8: 3000 | P8: GAW | R8: irasias@gmail.com | S8: 2000
A9: 46064 | B9: 57 | D9: 3 | E9: =SUM(D7:D11) -> 16 | I9: Close % | J9: =COUNTA(FEB_SHOWS[Closed?])/J7 -> 0.39130435 | M9: windowwashingwarriors@gmail.com | N9: 46063 | P9: Boardroom
A10: 46065 | B10: 75 | D10: 3 | I10: Total Rev Sourced | J10: =SUM(FEB_SHOWS[Closed?]) -> 65500 | M10: howdy@doubleornothingtwostep.com | N10: 46063 | P10: Boardroom
A11: 46066 | B11: 39 | D11: 3 | I11: Personal Rev Collected | J11: =SUM(Table5[$]) -> 7250 | K11: Commission: | L11: =J11*0.2 -> 1450 | M11: meg@traveluxe.com | N11: 46063 | O11: 24000 | P11: Boardroom
A12: 46069 | E12: OOO | I12: Total Rev: | J12: =SUM(J10:J11) -> 72750 | M12: Chris Edwards | N12: 46064 | P12: Boardroom
A13: 46070 | M13: Andres Moran | N13: 46064 | P13: Boardroom
A14: 46071 | D14: 1 | M14: micahfairchild5@gmail.com | N14: 46066 | O14: 11500 | P14: Academy
A15: 46072 | D15: 1 | I15: % to Goal | J15: =J7/40*100 -> 57.5 | K15: =J7*62.5 -> 1437.5 | M15: hopejan12@gmail.com | N15: 46066 | O15: 2000 | P15: GAW
A16: 46073 | I16: % to EOM | J16: =DAY(TODAY()) / DAY(EOMONTH(TODAY(), 6))*100 -> 70.967742 | K16: =1666+((K15+L11)*0.71) -> 3716.125 | M16: jclarken@gmail.com | N16: 46066 | O16: 12000 | P16: Boardroom
A17: 46074 | M17: clint4pres@gmail.com | N17: 46066 | P17: Academy
A18: 46075 | M18: A'Lexus French | N18: 46066 | O18: 4500 | P18: GAW
A19: 46076 | I19: ALL TIME DESK REV | J19: ='Ben Jan 26'!G32+J12 -> 219597 | M19: drjaylenebair@gmail.com | N19: 46066 | P19: Boardroom
A20: 46077 | M20: info@advanced247restoration.com | N20: 46069 | P20: Boardroom
A21: 46078 | M21: Lori Newell | N21: 46069 | O21: 2500 | P21: GAW
A22: 46079 | M22: Jose Torres | N22: 46069 | P22: Boardroom
A23: 46080 | M23: ctshc88@gmail.com | N23: 46069 | P23: Boardroom
A24: 46081 | M24: hunter@theunclegroup.com | N24: 46072 | P24: Academy
M25: amandawilson@deerfootlodge.com | N25: 46063 | O25: 4000 | P25: GAW

Sheet Adrian Feb 26
A1: Date: | B1: Calls Made: | C1: Calls Answered: | D1: Demos Booked: | E1: Column 1 | F1: Total Calls Made | G1: =SUM(FEBUARY_DASH[Calls Made:]) -> 0 | J1: CALLS SHOWN: | K1: Date: | L1: Closed? | M1: Product
A2: 46055 | D2: 2 | F2: Total calls answered | G2: =SUM(FEBUARY_DASH[Calls Answered:]) -> 0 | J2: gary@oraclehomes.com | K2: 46055 | M2: Academy
A3: 46056 | D3: 2 | F3: Total Demos Booked | G3: =SUM(FEB_DASH[Demos Booked:]) -> 27 | J3: bseims1@gmail.com | K3: 46056 | M3: Academy
A4: 46057 | D4: 4 | F4: Ave calls/day | G4: =SUM(FEBUARY_DASH[Calls Made:])/COUNTA(FEBUARY_DASH[Calls Made:]) -> #DIV/0! | J4: imran.khawaja@mdtrucare.com | K4: 46057 | M4: GAW
A5: 46058 | D5: 0 | F5: Demos booked/day | G5: =G3/COUNTA(FEBUARY_DASH[Demos Booked:]) -> 1.9285714 | J5: Paulinecastro11@gmail.com | K5: 46057 | L5: 12000 | M5: Boardroom | O5: Prev Month | P5: $ | Q5: Column 1 | S5: GAW | T5: $ | U5: Column 1 | V5: Column 2
A6: 46059 | D6: 3 | F6: Answer % | G6: =G2/G1 -> #DIV/0! | J6: r.preis@airstreaminc.ca | K6: 46058 | M6: Boardroom | O6: Kobus Le Roux | P6: 12000 | Q6: First call in Jan/ close in Feb | S6: eliza@oatmama.com | T6: 3000 | U6: 46055 | V6: commision
A7: 46060 | F7: Set % | G7: =G3/G2 -> #DIV/0! | J7: miranda@3chousenv.com | K7: 46059 | L7: 12000 | M7: Boardroom | O7: Kobus Le Roux | P7: 2500 | Q7: GAW | S7: berel@maplestmanagement.com | T7: 2500 | U7: 46057 | V7: commision
A8: 46061 | F8: Total Demos Complete | G8: =COUNTA(FEBUARY_SHOWS[CALLS SHOWN:]) -> 22 | J8: neltao@gmail.com | K8: 46062 | M8: GAW | O8: rachael@readonroads.com | P8: 2500 | Q8: Kobus (partner) | S8: adam@macont.com) | T8: 3000 | U8: 46062 | V8: 2 tickets
A9: 46062 | D9: 5 | F9: Show % | G9: =COUNTA(FEBUARY_SHOWS[CALLS SHOWN:])/G3 -> 0.81481481 | J9: kashudd@yahoo.com | K9: 46062 | M9: GAW | O9: craig@readonroads.com | P9: 2500 | Q9: Kobus (partner) | S9: adam@macont.com) | T9: 1500 | U9: 46062 | V9: brother
A10: 46063 | D10: 1 | F10: Close % | G10: =COUNTA(FEBUARY_SHOWS[Closed?])/G8 -> 0.13636364 | J10: tim@matthewsgrowthpartners.com | K10: 46062 | M10: Boardroom | S10: Anastasia Evstarti | T10: 1500 | U10: 46070 | V10: 1 ticket
A11: 46064 | D11: 2 | E11: =SUM(D9:D13) -> 15 | F11: Total Rev Sourced | G11: =SUM(FEBUARY_SHOWS[Closed?]) -> 33500 | J11: bennett8205@yahoo.com | K11: 46064 | M11: Boardroom
A12: 46065 | D12: 3 | F12: Total Personal Rev | G12: 11500 | J12: kelliraerowan@gmail.com | K12: 46064 | L12: 9500 | M12: Academy
A13: 46066 | D13: 4 | F13: Total Outbound Rev | G13: =SUM(G11:G12)+SUM(Table7[$]) -> 64500 | J13: craigselvitella@yahoo.com | K13: 46065 | M13: Academy | V13: Commission:
A14: 46067 | J14: basu.debdeep@gmail.com | K14: 46066 | M14: Academy | V14: =SUM(T6:T7)*0.2 -> 1100
A15: 46068 | J15: info@dynamicincorporated.com | K15: 46066 | M15: Academy
A16: 46069 | D16: 4 | F16: % to Goal | G16: =G8/40*100 -> 55 | H16: =G8*61.5 -> 1353 | J16: joe@bachmeierpm.com | K16: 46066 | M16: GAW
A17: 46070 | D17: 2 | F17: % to EOM | G17: =DAY(TODAY()) / DAY(EOMONTH(TODAY(), 6))*100 -> 70.967742 | H17: =1666+((H16+I14)*0.71)+(V14) -> 3726.63 | J17: ean.lowell@gmail.com | K17: 46069 | M17: BR --> GAW
A18: 46071 | D18: 2 | J18: abeer.nagi@gmail.com | K18: 46069 | M18: Academy
A19: 46072 | D19: 1 | J19: erin@efdesigns.co | K19: 46070 | M19: Academy
A20: 46073 | J20: claudia.alamo1723@gmail.com | K20: 46070 | M20: Academy
A21: 46074 | J21: britojosa@yahoo.com | K21: 46071 | M21: Boardroom
A22: 46075 | F22: Future booked: | J22: dynamic.lv.bookkeeping@gmail.com | K22: 46072 | M22: Academy
F23: priscillabaier@icloud.com | J23: eric@natayconstruction.com | K23: 46073 | M23: BR--> GAW
F24: admin@thinkoutsidethestocks.com | peyooshmadhavi@gmail.com
A27: No shows: | C27: Adrian No Shows
A28: herrerke09@gmail.com | C28: office@solutionpeptides.net
A29: june061514@gmail.com | C29: herrerke09@gmail.com
A30: kashudd@yahoo.com | C30: june061514@gmail.com
C31: info@northstarhalibut.com

Sheet Jan Dash
A1: Total Demos Set: | B1: Total Demos Shown: | C1: Total Outbound Rev:
A2: =SUM(Jan[Demos Booked:])+SUM(Table2[Demos Booked:]) -> 111 | B2: =COUNTA(Jan_Shows[CALLS SHOWN:])+COUNTA(Table3[CALLS SHOWN:0]) -> 79 | C2: =SUM(Jan_Shows[Closed?])+SUM(Table3[Closed?])+SUM(PM[Close?])+SUM(GAW[Close?])+SUM(Table4[Close $]) -> 185250 | E2: % to Goal: | F2: =C2/150000 -> 1.235
E3: % to EOM: | F3: =DAY(TODAY()) / DAY(EOMONTH(TODAY(), 6))*100 -> 70.967742

Sheet Ben Jan 26
A1: Date: | B1: Calls Made: | C1: Calls Answered: | D1: Demos Booked: | E1: Column 1
A2: 46027 | B2: 12 | C2: 4 | D2: 4 | F2: Total Calls Made | G2: 1027
A3: 46028 | B3: 53 | C3: 12 | D3: 6 | E3: Week 1: | F3: Total calls answered | G3: =SUM(Jan[Calls Answered:]) -> 154 | I3: CALLS SHOWN: | J3: Date: | K3: Closed? | L3: Column 1 | M3: NO SHOW: | N3: Date:
A4: 46029 | B4: 51 | C4: 9 | D4: 5 | E4: =SUM(D2:D6) -> 18 | F4: Total Demos Booked | G4: =SUM(Jan[Demos Booked:]) -> 60 | I4: jeff.holmes@hey.com | J4: 46028 | K4: 9600 | M4: susan@guidepostpediatrics.com | N4: 46031
A5: 46030 | B5: 55 | C5: 9 | D5: 2 | F5: Ave calls/day | G5: =G2/COUNTA(B2:B21) -> 51.35 | I5: ozzyisabu@gmail.com | J5: 46029 | M5: yumei chen | N5: 46035
A6: 46031 | B6: 47 | C6: 8 | D6: 1 | F6: Demos booked/day | G6: =SUM(G4)/COUNTA(D2:D21) -> 3 | I6: kl@thesalarybump.com | J6: 46029 | K6: 2750 | L6: GAW | M6: Clara della tonga | N6: 46035
A7: 46034 | B7: 57 | C7: 9 | D7: 1 | F7: Answer % | G7: =SUM(G3)/G2 -> 0.14995131 | I7: suzieaustin@kw.com | J7: 46030
A8: 46035 | B8: 73 | C8: 18 | D8: 6 | E8: Week 2: | F8: Dials/Demo | G8: =SUM(G2)/G4 -> 17.116667 | I8: Venkatesh Maran | J8: 46031
A9: 46036 | B9: 22 | C9: 8 | D9: 3 | E9: =SUM(D7:D11) -> 20 | F9: Set % | G9: =SUM(D2:D21)/SUM(C2:C21) -> 0.38961039 | I9: patrick@complete-electric.net | J9: 46031
A10: 46037 | B10: 89 | C10: 13 | D10: 7 | F10: Total Demos Complete | G10: =COUNTA(Jan_Shows[CALLS SHOWN:]) -> 42 | I10: mario@ppgsecurity.com | J10: 46031
A11: 46038 | B11: 36 | C11: 5 | D11: 3 | F11: Show % | G11: =COUNTA(Jan_Shows[CALLS SHOWN:])/G4 *100 -> 70 | I11: jack.barnett.92@gmail.com | J11: 46031
A12: 46041 | B12: 62 | C12: 5 | D12: 1 | F12: Close % | G12: =COUNTA(Jan_Shows[Closed?])/COUNTA(Jan_Shows[CALLS SHOWN:]) *100 -> 26.190476 | I12: gopalpagarani@hotmail.com | J12: 46035 | M12: GAW | N12: Close?
A13: 46042 | B13: 118 | C13: 5 | D13: 2 | E13: Week 3: | F13: Total Rev Sourced | G13: =SUM(Jan_Shows[Closed?])+SUM(GAW[Close?])+SUM(PM[Close?]) -> 84650 | I13: Lynn Williams | J13: 46035 | K13: 2000 | L13: AF | M13: tom chandler | N13: 2500
A14: 46043 | B14: 25 | C14: 5 | D14: 4 | E14: =SUM(D12:D16) -> 16 | F14: Personal Rev Collected | G14: =SUM(Rev[$]) -> 4697 | I14: Isaac Garcia | J14: 46035
A15: 46044 | B15: 54 | C15: 11 | D15: 7 | F15: Total Rev: | G15: =SUM(G13:G14) -> 89347 | I15: Thenamudhan K | J15: 46036 | K15: 9600
A16: 46045 | B16: 46 | C16: 5 | D16: 2 | I16: todd@hilltreekeepers.com | J16: 46037
A17: 46048 | B17: 53 | C17: 4 | D17: 2 | I17: msayibucpa20@gmail.com | J17: 46037
A18: 46049 | B18: 50 | C18: 11 | D18: 2 | E18: Week 4: (GAW Outbound focused) | I18: Brian Anderson | J18: 46037 | M18: Past Months: | N18: Close?
A19: 46050 | B19: 56 | C19: 7 | D19: 1 | E19: =SUM(D17:D19) -> 5 | I19: liz.michelle@hotmail.com | J19: 46037 | M19: Freddy Rojas | N19: 9600
A20: 46051 | B20: 35 | C20: 3 | D20: 1 | I20: vanessasimkins@yahoo.com | J20: 46038
A21: 46052 | B21: 40 | C21: 3 | D21: 0 | I21: ravitzmarianna@gmail.com | J21: 46041
F22: % to Goal | G22: =G10/60*100 -> 70 | I22: tiffany@thefarmerandchef.com | J22: 46041 | K22: 9500
F23: % to EOM | G23: =DAY(TODAY()) / DAY(EOMONTH(TODAY(), 6))*100 -> 70.967742 | I23: Rachel Cardoso | J23: 46041
I24: chericgsflooring@gmail.com | J24: 46042
I25: Ray Pena | J25: 46042
I26: Scott Oldner | J26: 46043
F27: Personal Close: | G27: $ | I27: nathan.leishman.15@gmail.com | J27: 46043 | K27: 1500
F28: linda steen (renewal) | G28: 4500 | I28: michaelmmehta@gmail.com | J28: 46043
F29: Lynn Williams (MSML) | G29: 197 | I29: justin@fourpillarcapital.com | J29: 46045
I30: dwilczynski@live.com | J30: 46045 | K30: 2000 | L30: AF
I31: adnanchowdhury604@gmail.com | J31: 46045
F32: ALL TIME REV | G32: =SUM(Calls_Shown_Dec[Close?])+G15 -> 146847 | I32: prital@psarchdesign.com | J32: 46046
I33: ilosey60@gmail.com | J33: 46048
I34: Bobby Hall | J34: 46048 | K34: 9500
I35: Sandra Morales | J35: 46048
I36: wutichai@hotmail.com | J36: 46048
I37: mark@deerfieldbuilders.com | J37: 46049 | K37: 9600
I38: hamish.patterson@kormax.com | J38: 46049
I39: antonio@adventuresgroup.us | J39: 46049
I40: Aamer Rehman | J40: 46049
...

Sheet Adrian Jan 26
A1: I'm pretty confident about the numbers we have, so I think for Ben it's pretty clear. Total refs sourced is 84650 and | B1: Calls Made: | C1: Calls Answered: | D1: Demos Booked: | E1: Column 1
A2: 46027 | B2: 2 | D2: 0 | E2: =SUM(D2:D6) -> 12 | F2: Total calls made | G2: =SUM(Table2[Calls Made:]) -> 612
A3: 46028 | B3: 36 | D3: 4 | F3: Total calls answered | G3: =SUM(Table2[Calls Answered:]) -> 0 | I3: CALLS SHOWN:0 | J3: Date: | K3: Closed? | L3: Column 1
A4: 46029 | B4: 64 | D4: 6 | F4: Total Demos Booked | G4: =SUM(Table2[Demos Booked:]) -> 51 | I4: kgjessop1@hotmail.com | J4: 46024
A5: 46030 | B5: 21 | D5: 1 | F5: Ave calls/day | G5: =SUM(Table2[Calls Made:])/COUNTA(Table2[Calls Made:]) -> 38.25
A6: 46031 | B6: 10 | D6: 1 | F6: Demos booked/day | G6: =SUM(G4)/COUNTA(Table2[Demos Booked:]) -> 3.1875 | I6: lori@lori-mcintosh.com | J6: 46029
A7: 46034 | B7: 4 | D7: 0 | F7: Answer % | G7: =SUM(G3)/G2 -> 0 | I7: michellehe@gmail.com | J7: 46030 | K7: 9500
A8: 46035 | B8: 62 | D8: 5 | F8: Answered calls/demo booked | G8: =SUM(G3)/G4 -> 0 | I8: jeremy.rcmllc@gmail.com | J8: 46031
A9: 46036 | B9: 13 | D9: 3 | E9: =SUM(D7:D11) -> 17 | F9: Dials/Demo | G9: =SUM(G2)/G4 -> 12 | I9: rachel@idahoelitek9.com | J9: 46034
A10: 46037 | B10: 14 | D10: 6 | F10: Total Demos Complete | G10: =COUNTA(Table3[CALLS SHOWN:0]) -> 37
A11: 46038 | B11: 52 | D11: 3 | F11: % to Goal | G11: =G10/60*100 -> 61.666667 | I11: KATIE DRISCOLL consolejesus@icloud.com | J11: 46037 | K11: 12000 | L11: mc
A12: 46041 | B12: 58 | D12: 2 | F12: Total Rev | G12: =SUM(Table3[Closed?]) -> 88600 | I12: mlbrooks_88@hotmail.com | J12: 46038 | L12: not mc
A13: 46042 | B13: 77 | D13: 1 | E13: =SUM(D12:D16) -> 16 | I13: saltabuena@hotmail.com | J13: 46038 | K13: 12000 | L13: mc
A14: 46043 | B14: 83 | D14: 5
A15: 46044 | B15: 13 | D15: 3 | I15: shawn.joseph.mcintosh@gmail.com | J15: 46041 | K15: 12000
A16: 46045 | B16: 36 | D16: 5 | I16: jenniferdwatts@gmail.com | J16: 46041 | L16: academy
A17: 46048 | B17: 67 | D17: 6 | I17: xenabonet@gmail.com | J17: 46042
A18: 46049 | I18: bridgetdennin@gmail.com | J18: 46042 | K18: 12000
A19: 46050 | I19: michaelvincent.inc@gmail.com | J19: 46042
A20: 46051 | I20: kobus@readonroads.com | J20: 46042 | L20: FEB CLOSE
A21: 46052 | F21: % to Goal | G21: =G10/60*100 -> 61.666667 | I21: joan.cassidy@squeezemassage.com | J21: 46042
F22: % to EOM | G22: =DAY(TODAY()) / DAY(EOMONTH(TODAY(), 6))*100 -> 70.967742 | I22: perfectpourdano@gmail.com | J22: 46043 | L22: turned into GAW
I23: chrisd159753@gmail.com | J23: 46044
I24: ozzieinvest@gmail.com | J24: 46044 | L24: academy
I25: ciigconsulting@outlook.com | J25: 46044
I26: moeedahmed1@gmail.com | J26: 46045
A27: No Shows Adrian Inbound: | D27: No Shows for AE's Jan: | I27: kortinc@yahoo.com | J27: 46045
A28: davila24@icloud.com | D28: maya@cforceglobal.com | I28: cody@bdforensics.com | J28: 46045 | L28: build
A29: joao.carrilho@jlcenergy.pt | B29: portugal | D29: david@woodlanderworkshop.com | I29: thecleanmachine25@gmail.com | J29: 46045 | K29: 9600
A30: saycapitalholdings@gmail.com | D30: Telesforo Uribe | I30: vbrown@birminghambusinessalliance.com | J30: 46045
A31: sandra.jitianu@ideograf.ro | D31: limitlessamx@gmail.com | I31: ar2romc88@gmail.com | J31: 46046
A32: cretu.artur@gmail.com | D32: arswengel@gmail.com (follow up Tues) | I32: jamesr@zeonsignsnm.com | J32: 46048 | K32: 12000
A33: kevin.coffman7@gmail.com | I33: lusiaespinoza@yahoo.com | J33: 46049
I34: tantalus@gmail.com | J34: 46049 | K34: 9500
I35: jorge@topchoicetransport.net | J35: 46050 | O35: =G10*41.66 -> 1541.42 | P35: =1666+(O35*0.71) -> 2760.4082
A36: Adrian Future Oppertunity: | I36: michaelchao@gmail.com | J36: 46050
A37: khanaak@gmail.com | B37: (low intent) | I37: nazano@yahoo.com | J37: 46050
A38: leahlaxlax@gmail.com | B38: (needs more info) | I38: holyfireic@gmail.com | J38: 46050
A39: g18trucking@gmail.com | B39: (financial DQ*) | F39: Booked Future: | I39: leahlaxlax@gmail.com | J39: 46051
A40: jamienpeta@gmail.com | I40: g18trucking@gmail.com | J40: 46051
...

Sheet Ben Dec 25
A1: Date | B1: Calls Made | C1: Calls Answered | D1: Demos Booked | E1: Column 1 | F1: Column 2
A2: 45992 | B2: 126 | C2: 8 | D2: 4
A3: 45993 | B3: 152 | C3: 19 | D3: 3 | F3: =SUM(D2:D6) -> 22 | G3: CALLS SHOWN Dec: 45 | H3: Column 2 | I3: Close? | K3: TOTAL REV: | L3: =SUM(Calls_Shown_Dec[[#ALL],[Close?]]) -> 57500
A4: 45994 | B4: 115 | C4: 23 | D4: 5 | G4: nickrileydriftwood@gmail.com | H4: 45992
A5: 45995 | B5: 96 | C5: 14 | D5: 5 | G5: a.romero0024@gmail.com | H5: 45994
A6: 45996 | B6: 101 | C6: 17 | D6: 5 | G6: Wick Vipond | H6: 45994 | K6: Closed
A7: 45999 | B7: 29 | C7: 7 | D7: 1 | G7: limon.thomas@icloud.com | H7: 45995 | K7: WFS
A8: 46000 | B8: 131 | C8: 18 | D8: 2 | G8: Doeothy Kawula | H8: 45995
A9: 46001 | B9: 185 | C9: 25 | D9: 11 | F9: =SUM(D7:D11) -> 22 | G9: jill@ryanhousecandles.com | H9: 45996
A10: 46002 | C10: 2 | D10: 2 | E10: Training | G10: Tom Chandler | H10: 45996
A11: 46003 | B11: 112 | C11: 17 | D11: 6 | G11: Madison Hecker | H11: 45995
A12: 46006 | C12: 0 | E12: Sick | G12: limon.thomas@icloud.com | H12: 45996
A13: 46007 | B13: 20 | C13: 5 | D13: 2 | F13: =SUM(D12:D16) -> 12 | G13: Rod Rose | H13: 45995
A14: 46008 | D14: 2 | G14: Ming Fang | H14: 45999
A15: 46009 | B15: 71 | C15: 19 | D15: 5 | G15: mhorowitz227@outlook.com | H15: 45999
A16: 46010 | B16: 63 | C16: 7 | D16: 3 | G16: Magda | H16: 46001 | I16: 12000
A17: 46013 | B17: 0 | C17: 0 | D17: 2 | G17: jacksondcooper@gmail.com | H17: 46001
A18: 46014 | B18: 0 | C18: 0 | D18: 1 | G18: Freddy Rojas | H18: 46001
G19: ed.kidney@gmail.com | H19: 46002 | I19: 9500
G20: Anthony T Fischetti | H20: 46003
A21: Total calls made | B21: 1290 | G21: scott.goodman@rocketmail.com | H21: 46003
A22: Total calls answered | B22: =SUM(Dec[Calls Answered]) -> 181 | G22: Raymond Brunner | H22: 46003
A23: Total Demos Booked | B23: =SUM(Dec[Demos Booked]) -> 59 | G23: Douglas MacIver | H23: 46003
A24: Calls/Day | B24: =1290/COUNTA(Dec[Date]) -> 75.882353 | G24: David - Thai Topaz | H24: 46003
A25: Demos booked/day | B25: =AVERAGE(Dec[Demos Booked]) -> 3.6875 | D25: TOTAL REV: | E25: =SUM(Calls_Shown_Dec[[#ALL],[Close?]]) -> 57500 | G25: Fady Saad | H25: 46003
A26: Answer % | B26: =B22/B21*100 -> 14.031008 | G26: Noel Swinburne | H26: 46003
A27: Answered call/booked | B27: =((SUM(Dec[Calls Answered]))/SUM(Dec[Demos Booked])) -> 3.0677966 | G27: Rodrigo Sartori | H27: 46006
A28: Dials/Demo | B28: =B21/B23 -> 21.864407 | G28: Justin Van Hill | H28: 46006
A29: Set % | B29: =SUM(Dec[Demos Booked])/SUM(Dec[Calls Answered])*100 -> 32.596685 | G29: Cole Watson | H29: 46006
A30: Total Demos Complete | B30: =COUNTA(Calls_Shown_Dec[CALLS SHOWN Dec: 45]) -> 45 | G30: anthony_dat@hotmail.com | H30: 46006
A31: % to Goal | B31: =B30/40*100 -> 112.5 | G31: hasnain hani | H31: 46007
A32: Total Pipeline | B32: 658500 | G32: Victor Obiri | H32: 46007
A33: Total Rev Collected | B33: =SUM(Calls_Shown_Dec[Close?]) -> 57500 | G33: Vincent Fallourd | H33: 46007
A34: Call Show % | B34: =B30/B23*100 -> 76.271186 | G34: Sean Aaron | H34: 46007
A35: Call Close % | B35: =5/45*100 -> 11.111111 | G35: Anatoli Lukkarinen | H35: 46008
G36: Robert Belcher | H36: 46007
G37: Christopher Ball | H37: 46008 | I37: 12000
G38: Mary Soldano | H38: 46009 | I38: 12000
G39: Baltazar Pena | H39: 46009
G40: Bayard Hogans | H40: 46010
...

Sheet GAW BREAKDOWN
A1: TICKETS CLOSED BY REP
A3: Rep | B3: Deals Closed | C3: Tickets Closed | D3: Revenue | E3: Outbound Tickets | F3: Inbound Tickets
A4: Mel Fox | B4: 13 | C4: 16 | D4: 34500 | E4: 8 | F4: 8
A5: Alex Chavez | B5: 5 | C5: 5 | D5: 13500 | E5: 3 | F5: 2
A6: Adrian Delaney | B6: 3 | C6: 5 | D6: 9000 | E6: 5 | F6: 0
A7: Dani Ruadez | B7: 2 | C7: 3 | D7: 8750 | E7: 1 | F7: 2
A8: Ben Averbook | B8: 2 | C8: 2 | D8: 5250 | E8: 2 | F8: 0
A9: Preston Palmer | B9: 1 | C9: 1 | D9: 3000 | E9: 0 | F9: 1
A10: TOTAL | B10: 24 | C10: 29 | D10: 72500 | E10: 18 | F10: 11
A13: TICKETS SOURCED BY BDR (OUTBOUND)
A15: BDR | B15: Deals Sourced | C15: Tickets Sourced | D15: Also Closed (Self) | E15: Self-Close Tickets | F15: Handed Off Tickets
A16: Ben Averbook | B16: 8 | C16: 11 | D16: 2 | E16: 3 | F16: 8
A17: Adrian Delaney | B17: 6 | C17: 7 | D17: 3 | E17: 5 | F17: 3
A18: TOTAL OUTBOUND | B18: 14 | C18: 18 | D18: 5 | E18: 8 | F18: 11
A21: INBOUND TICKETS (NO BDR TAG)
A23: Closer | B23: Inbound Deals | C23: Inbound Tickets | D23: Revenue
A24: Mel Fox | B24: 8 | C24: 8 | D24: 22000
A25: Alex Chavez | B25: 2 | C25: 2 | D25: 6000
A26: Dani Ruadez | B26: 1 | C26: 2 | D26: 6000
A27: Preston Palmer | B27: 1 | C27: 1 | D27: 3000

Sheet 1-14 MC Detail
A1: 1/14 MASTERCLASS: OUTBOUND vs INBOUND BY AE
A3: AE | B3: Source | C3: Total | D3: No Shows | E3: Shows | F3: Show % | G3: Won | H3: Lost | I3: Close % | J3: Revenue
A4: Mel Fox | B4: Outbound | C4: 2 | D4: 1 | E4: 1 | F4: 50% | G4: 1 | H4: 0 | I4: 100.0% | J4: 12000
A5: Mel Fox | B5: Inbound | C5: 15 | D5: 6 | E5: 9 | F5: 60% | G5: 0 | H5: 3 | I5: 0.0% | J5: 0
A7: Preston Palmer | B7: Outbound | C7: 11 | D7: 2 | E7: 9 | F7: 82% | G7: 2 | H7: 2 | I7: 22.2% | J7: 24000
A8: Preston Palmer | B8: Inbound | C8: 2 | D8: 0 | E8: 2 | F8: 100% | G8: 0 | H8: 1 | I8: 0.0% | J8: 0
A10: Dani Ruadez | B10: Outbound | C10: 5 | D10: 1 | E10: 4 | F10: 80% | G10: 2 | H10: 0 | I10: 50.0% | J10: 24000
A11: Dani Ruadez | B11: Inbound | C11: 12 | D11: 3 | E11: 9 | F11: 75% | G11: 3 | H11: 5 | I11: 33.3% | J11: 36000
A13: Alex Chavez | B13: Outbound | C13: 10 | D13: 2 | E13: 8 | F13: 80% | G13: 2 | H13: 2 | I13: 25.0% | J13: 24000
A14: Alex Chavez | B14: Inbound | C14: 6 | D14: 2 | E14: 4 | F14: 67% | G14: 0 | H14: 0 | I14: 0.0% | J14: 0
A16: Adrian Delaney | B16: Outbound | C16: 1 | D16: 0 | E16: 1 | F16: 100% | G16: 0 | H16: 1 | I16: 0.0% | J16: 0
A19: TOTALS
A20: ALL | B20: Outbound | C20: 29 | D20: 6 | E20: 23 | F20: 79% | G20: 7 | H20: 5 | I20: 30.4% | J20: 84000
A21: ALL | B21: Inbound | C21: 37 | D21: 11 | E21: 26 | F21: 70% | G21: 3 | H21: 9 | I21: 11.5% | J21: 36000

Sheet 1-21 MC Detail
A1: 1/21 MASTERCLASS: OUTBOUND vs INBOUND BY AE
A3: AE | B3: Source | C3: Total | D3: No Shows | E3: Shows | F3: Show % | G3: Won | H3: Lost | I3: Close % | J3: Revenue
A4: Mel Fox | B4: Outbound | C4: 5 | D4: 1 | E4: 4 | F4: 80% | G4: 2 | H4: 0 | I4: 50.0% | J4: 19100
A5: Mel Fox | B5: Inbound | C5: 14 | D5: 3 | E5: 11 | F5: 79% | G5: 3 | H5: 6 | I5: 27.3% | J5: 27450
A7: Preston Palmer | B7: Outbound | C7: 3 | D7: 1 | E7: 2 | F7: 67% | G7: 1 | H7: 0 | I7: 50.0% | J7: 9500
A8: Preston Palmer | B8: Inbound | C8: 21 | D8: 4 | E8: 17 | F8: 81% | G8: 3 | H8: 11 | I8: 17.6% | J8: 27650
A10: Dani Ruadez | B10: Outbound | C10: 10 | D10: 2 | E10: 8 | F10: 80% | G10: 1 | H10: 2 | I10: 12.5% | J10: 2000
A11: Dani Ruadez | B11: Inbound | C11: 21 | D11: 3 | E11: 18 | F11: 86% | G11: 3 | H11: 7 | I11: 16.7% | J11: 28600
A13: Alex Chavez | B13: Outbound | C13: 11 | D13: 1 | E13: 10 | F13: 91% | G13: 3 | H13: 1 | I13: 30.0% | J13: 28800
A14: Alex Chavez | B14: Inbound | C14: 13 | D14: 1 | E14: 12 | F14: 92% | G14: 1 | H14: 2 | I14: 8.3% | J14: 2000
A16: Adrian Delaney | B16: Inbound | C16: 3 | D16: 0 | E16: 3 | F16: 100% | G16: 0 | H16: 0 | I16: 0.0% | J16: 0
A19: TOTALS
A20: ALL | B20: Outbound | C20: 29 | D20: 5 | E20: 24 | F20: 83% | G20: 7 | H20: 3 | I20: 29.2% | J20: 59400
A21: ALL | B21: Inbound | C21: 72 | D21: 11 | E21: 61 | F21: 85% | G21: 10 | H21: 26 | I21: 16.4% | J21: 85700
